---
description: 'Altre informazioni su: C28125'
title: C28125
ms.date: 11/04/2016
ms.topic: reference
f1_keywords:
- C28125
helpviewer_keywords:
- C28125
ms.assetid: 3f7b8db4-6a64-4480-919e-3f3ceca7f948
ms.openlocfilehash: abbcc0a89dd2d57ce34ef9d00acb6e79354d6d94
ms.sourcegitcommit: d6af41e42699628c3e2e6063ec7b03931a49a098
ms.translationtype: MT
ms.contentlocale: it-IT
ms.lasthandoff: 12/11/2020
ms.locfileid: "97151593"
---
# <a name="c28125"></a>C28125

> avviso C28125: la funzione deve essere chiamata dall'interno di un blocco try/except

Il driver chiama una funzione che deve essere chiamata dall'interno di un blocco try/except, ad esempio [probeForRead](/windows-hardware/drivers/ddi/content/wdm/nf-wdm-probeforread), [ProbeForWrite](/windows-hardware/drivers/ddi/content/wdm/nf-wdm-probeforwrite), [MmProbeAndLockPages](/windows-hardware/drivers/ddi/content/wdm/nf-wdm-mmprobeandlockpages).

## <a name="example"></a>Esempio

Nell'esempio riportato di seguito il codice genera questo avviso:

```cpp
ProbeForRead(addr, len, 4);
```

Nell'esempio riportato di seguito il codice evita questo avviso:

```cpp
__try
{
    ProbeForRead(addr, len, 4);
}
__except(EXCEPTION_EXECUTE_HANDLER)
{
    Status = GetExceptionCode();
    ... report error status
}
```
